Workbook

Sheet File Gabungan Mitra
A1: TGL | B1: TID | C1: FITUR | D1: NOMINAL | E1: TRX | F1: FEE | G1: KB/AIO
A2: 46054 | B2: 67518569 | C2: CEK SALDO Prima | D2: 0 | E2: 1 | F2: 250 | G2: Mitra 1
A3: 46054 | B3: 66074693 | C3: Fund Transfer | D3: 3500000 | E3: 1 | F3: 250 | G3: Mitra 1
A4: 46054 | B4: 87928396 | C4: CEK SALDO Prima | D4: 500000 | E4: 1 | F4: 1000 | G4: Mitra 1
A5: 46054 | B5: 83530568 | C5: Tarik Tunai | D5: 1000000 | E5: 1 | F5: 1000 | G5: Mitra 1
A6: 46054 | B6: 81558920 | C6: Pembelian Pulsa | D6: 500000 | E6: 1 | F6: 1550 | G6: Mitra 1
A7: 46054 | B7: 79072817 | C7: Tarik Tunai | D7: 0 | E7: 1 | F7: 1000 | G7: Mitra 1
A8: 46054 | B8: 99401802 | C8: Pembelian Pulsa | D8: 100000 | E8: 1 | F8: 1000 | G8: Mitra 1
A9: 46054 | B9: 79294663 | C9: Pembayaran PLN | D9: 0 | E9: 1 | F9: 600 | G9: Mitra 1
A10: 46054 | B10: 63254090 | C10: CEK SALDO | D10: 1000000 | E10: 1 | F10: 600 | G10: Mitra 1
A11: 46054 | B11: 68647257 | C11: Pembelian Pulsa | D11: 3500000 | E11: 1 | F11: 600 | G11: Mitra 1
A12: 46054 | B12: 81309880 | C12: Pembayaran PLN | D12: 1500000 | E12: 1 | F12: 250 | G12: Mitra 1
A13: 46054 | B13: 62870935 | C13: Pembayaran PLN | D13: 0 | E13: 1 | F13: 1000 | G13: Mitra 1
... A3333: 46081 | B3333: 60303264 | C3333: Top Up | D3333: 0 | E3333: 1 | F3333: 1000 | G3333: Mitra 1
C3334: FITUR | G3334: KB/AIO
A3335: 46054 | B3335: 81713376 | C3335: CEK SALDO | D3335: 0 | E3335: 1 | F3335: 600 | G3335: MITRA 2
A3336: 46054 | B3336: 73981838 | C3336: CEK SALDO Prima | D3336: 250000 | E3336: 1 | F3336: 1550 | G3336: MITRA 2
A3337: 46054 | B3337: 69224076 | C3337: CEK SALDO | D3337: 200000 | E3337: 1 | F3337: 600 | G3337: MITRA 2
A3338: 46054 | B3338: 90978861 | C3338: CEK SALDO | D3338: 3500000 | E3338: 1 | F3338: 1550 | G3338: MITRA 2
A3339: 46054 | B3339: 72569850 | C3339: Pembayaran PLN | D3339: 200000 | E3339: 1 | F3339: 250 | G3339: MITRA 2
A3340: 46054 | B3340: 95944596 | C3340: CEK SALDO Prima | D3340: 750000 | E3340: 1 | F3340: 1550 | G3340: MITRA 2
A3341: 46054 | B3341: 62666319 | C3341: Pembelian Pulsa | D3341: 3500000 | E3341: 1 | F3341: 250 | G3341: MITRA 2
A3342: 46054 | B3342: 60452405 | C3342: Top Up | D3342: 0 | E3342: 1 | F3342: 1550 | G3342: MITRA 2
A3343: 46054 | B3343: 67552802 | C3343: Fund Transfer | D3343: 2000000 | E3343: 1 | F3343: 250 | G3343: MITRA 2
A3344: 46054 | B3344: 92249964 | C3344: Pembayaran PLN | D3344: 0 | E3344: 1 | F3344: 1000 | G3344: MITRA 2
A3345: 46054 | B3345: 89930763 | C3345: Pembelian Pulsa | D3345: 5000000 | E3345: 1 | F3345: 250 | G3345: MITRA 2
A3346: 46054 | B3346: 75004578 | C3346: Top Up | D3346: 3500000 | E3346: 1 | F3346: 250 | G3346: MITRA 2
... A6694: 46081 | B6694: 64521979 | C6694: Pembayaran PLN | D6694: 50000 | E6694: 1 | F6694: 250 | G6694: MITRA 2
C6695: FITUR | G6695: KB/AIO
A6696: 46054 | B6696: 66959816 | C6696: CEK SALDO | D6696: 0 | E6696: 1 | F6696: 1000 | G6696: Mitra 3
A6697: 46054 | B6697: 82592972 | C6697: TRANSFER | D6697: 750000 | E6697: 1 | F6697: 600 | G6697: Mitra 3
A6698: 46054 | B6698: 79395903 | C6698: TRANSFER | D6698: 3500000 | E6698: 1 | F6698: 1000 | G6698: Mitra 3
A6699: 46054 | B6699: 71283437 | C6699: Fund Transfer | D6699: 500000 | E6699: 1 | F6699: 1550 | G6699: Mitra 3
A6700: 46054 | B6700: 90784812 | C6700: Fund Transfer | D6700: 100000 | E6700: 1 | F6700: 1550 | G6700: Mitra 3
A6701: 46054 | B6701: 74491111 | C6701: CEK SALDO Prima | D6701: 750000 | E6701: 1 | F6701: 1550 | G6701: Mitra 3
A6702: 46054 | B6702: 90209107 | C6702: Fund Transfer | D6702: 2000000 | E6702: 1 | F6702: 1550 | G6702: Mitra 3
A6703: 46054 | B6703: 91498196 | C6703: TRANSFER | D6703: 5000000 | E6703: 1 | F6703: 1550 | G6703: Mitra 3
A6704: 46054 | B6704: 67098265 | C6704: Top Up | D6704: 250000 | E6704: 1 | F6704: 250 | G6704: Mitra 3
A6705: 46054 | B6705: 88665212 | C6705: Tarik Tunai | D6705: 750000 | E6705: 1 | F6705: 600 | G6705: Mitra 3
A6706: 46054 | B6706: 96822433 | C6706: CEK SALDO | D6706: 0 | E6706: 1 | F6706: 1000 | G6706: Mitra 3
...

Sheet Sum TID
A1: {=_xlfn.UNIQUE(#REF!)} -> #REF! | F1: MAJU | H1: Melaju | K1: SALES MAJU | L1: >300 | M1: 100-299 | N1: <100 | P1: SALES MELAJU | Q1: >300 | R1: 100-299 | S1: <100
B2: {=IF(A2:A2000="","",SUMIFS(#REF!,#REF!,$A2:$A$2000))} | C2: {=IF(A2:A2000="","",(VLOOKUP(A2:A2000,#REF!,7,0)))} | D2: {=IF(A2:A2000="","",INDEX('[1]Data Master MAJU-MELAJU'!$U:$U,MATCH(A2:A2000,'[1]Data Master MAJU-MELAJU'!$C:$C,0)))} | F2: >300 | G2: =COUNTIFS(C:C,"MAJU", B:B,">300") -> 0 | H2: >300 | I2: =COUNTIFS(C:C,"Melaju", B:B,">300") -> 0 | K2: {=IFERROR(_xlfn.UNIQUE(D:D)," ")} -> 0 | L2: {=IF(A2:A2000="","",COUNTIFS($D:$D,K2:K2000,$B:$B,">300",$C:$C,"MAJU"))} | M2: {=IF(A2:A2000="","",COUNTIFS($D:$D,K2:K2000,$B:$B,">=100",$B:$B,"<300",$C:$C,"MAJU"))} | N2: {=IF(A2:A2000="","",COUNTIFS($D:$D,K2:K2000,$B:$B,"<100",$C:$C,"MAJU"))} | P2: {=IFERROR(_xlfn.UNIQUE(D:D)," ")} -> 0 | Q2: {=IF(A2:A2000="","",COUNTIFS($D:$D,K2:K2000,$B:$B,">300",$C:$C,"MELAJU"))} | R2: {=IF(A2:A2000="","",COUNTIFS($D:$D,K2:K2000,$B:$B,">=100",$B:$B,"<300",$C:$C,"MELAJU"))} | S2: {=IF(A2:A2000="","",COUNTIFS($D:$D,K2:K2000,$B:$B,"<100",$C:$C,"MELAJU"))}
F3: 100-299 | G3: =COUNTIFS(C:C,"MAJU", B:B,">=100", B:B,"<=299") -> 0 | H3: 100-299 | I3: =COUNTIFS(C:C,"Melaju", B:B,">=100", B:B,"<=299") -> 0
F4: <100 | G4: =COUNTIFS(C:C,"MAJU", B:B,"<100") -> 0 | H4: <100 | I4: =COUNTIFS(C:C,"Melaju", B:B,"<100") -> 0

Sheet Sum Febuari
A4: TGL | B4: TRANSAKSI | N4: TGL | O4: FEE
B5: MAJU | H5: MELAJU | O5: Cabang Jakarta | W5: Cabang Bandung
B6: KB | C6: AIO | D6: BAYAR | E6: CASHUP | F6: PPOB | G6: TARTUN | H6: KB | I6: AIO | J6: BAYAR | K6: PPOB | L6: TARTUN | O6: Mitra 1 | P6: Mitra 2 | Q6: Mitra 3 | R6: Mitra 4 | S6: Mitra 5 | T6: PPOB | U6: TARTUN | V6: TOTAL | W6: Mitra 6 | X6: Mitra 7 | Y6: Mitra 8 | Z6: PPOB | AA6: TARTUN | AB6: TOTAL
A7: 45992 | B7: {=SUMIFS(#REF!,#REF!,A7:A36,#REF!,"KB",#REF!,"MAJU")} -> #REF! | C7: {=SUMIFS(#REF!,#REF!,A7:A36,#REF!,"aio",#REF!,"MAJU")} -> #REF! | D7: {=_xlfn.ANCHORARRAY(F7)+_xlfn.ANCHORARRAY(G7)} -> #REF! | E7: {=SUMIFS(#REF!,#REF!,N7:N36,#REF!,"CashUp",#REF!,"MAJU")} -> #REF! | F7: {=IFERROR(INDEX('[2]SUM PPOB'!$B:$B,MATCH(A7:A36,'[2]SUM PPOB'!$D:$D,0)),)} -> 0 | G7: {=SUMIFS(#REF!,#REF!,A7:A36,#REF!,"bayar",#REF!,"MAJU")} -> #REF! | H7: {=SUMIFS(#REF!,#REF!,A7:A36,#REF!,"KB",#REF!,"Melaju")} -> #REF! | I7: {=SUMIFS(#REF!,#REF!,A7:A36,#REF!,"aio",#REF!,"Melaju")} -> #REF! | J7: {=_xlfn.ANCHORARRAY(K7)+_xlfn.ANCHORARRAY(L7)} -> #REF! | K7: {=IFERROR(INDEX('[3]SUM PPOB'!$B:$B,MATCH(A7:A36,'[3]SUM PPOB'!$D:$D,0)),)} -> 0 | L7: {=SUMIFS(#REF!,#REF!,A7:A36,#REF!,"bayar",#REF!,"Melaju")} -> #REF! | N7: 46054 | O7: {=SUMIFS('File Gabungan Mitra'!$F:$F,'File Gabungan Mitra'!$A:$A,N7:N37,'File Gabungan Mitra'!$G:$G,"Mitra 1")} -> 100900 | P7: {=SUMIFS('File Gabungan Mitra'!$F:$F,'File Gabungan Mitra'!$A:$A,N7:N37,'File Gabungan Mitra'!$G:$G,"Mitra 2")} -> 98950 | Q7: {=SUMIFS('File Gabungan Mitra'!$F:$F,'File Gabungan Mitra'!$A:$A,N7:N37,'File Gabungan Mitra'!$G:$G,"Mitra 3")} -> 263000 | R7: {=SUMIFS('File Gabungan Mitra'!$F:$F,'File Gabungan Mitra'!$A:$A,N7:N37,'File Gabungan Mitra'!$G:$G,"Mitra 4")} -> 101450 | S7: {=SUMIFS('File Gabungan Mitra'!$F:$F,'File Gabungan Mitra'!$A:$A,N7:N37,'File Gabungan Mitra'!$G:$G,"Mitra 5")} -> 97200 | T7: {=IFERROR(INDEX('[4]SUM PPOB'!$C:$C,MATCH(N7:N37,'[4]SUM PPOB'!$D:$D,0)),)} -> 19800 | U7: {=SUMIFS(#REF!,#REF!,N7:N37,#REF!,"bayar",#REF!,"MAJU")} -> #REF! | V7: {=_xlfn.ANCHORARRAY(O7)+_xlfn.ANCHORARRAY(P7)+_xlfn.ANCHORARRAY(Q7)+_xlfn.ANCHORARRAY(R7)} -> 564300 | W7: {=SUMIFS('File Gabungan Mitra'!$F:$F,'File Gabungan Mitra'!$A:$A,N7:N37,'File Gabungan Mitra'!$G:$G,"Mitra 6")} -> 243200 | X7: {=SUMIFS('File Gabungan Mitra'!$F:$F,'File Gabungan Mitra'!$A:$A,N7:N37,'File Gabungan Mitra'!$G:$G,"Mitra 7")} -> 70600 | Y7: {=SUMIFS('File Gabungan Mitra'!$F:$F,'File Gabungan Mitra'!$A:$A,N7:N37,'File Gabungan Mitra'!$G:$G,"Mitra 8")} -> 65800 | Z7: {=IFERROR(INDEX('[5]SUM PPOB'!$C:$C,MATCH(N7:N37,'[5]SUM PPOB'!$D:$D,0)),)} -> 20700 | AA7: {=SUMIFS(#REF!,#REF!,N7:N36,#REF!,"bayar",#REF!,"Melaju")} -> #REF! | AB7: =W7+X7+Y7 -> 379600
A8: 45993 | B8: #REF! | C8: #REF! | D8: #REF! | E8: #REF! | F8: 0 | G8: #REF! | H8: #REF! | I8: #REF! | J8: #REF! | K8: 0 | L8: #REF! | N8: 46055 | O8: 96450 | P8: 103900 | Q8: 252650 | R8: 99950 | S8: 90450 | T8: 18900 | U8: #REF! | V8: 552950 | W8: 255550 | X8: 67300 | Y8: 65500 | Z8: 6300 | AA8: #REF! | AB8: =W8+X8+Y8 -> 388350
A9: 45994 | B9: #REF! | C9: #REF! | D9: #REF! | E9: #REF! | F9: 0 | G9: #REF! | H9: #REF! | I9: #REF! | J9: #REF! | K9: 0 | L9: #REF! | N9: 46056 | O9: 94900 | P9: 97250 | Q9: 266500 | R9: 102550 | S9: 94100 | T9: 0 | U9: #REF! | V9: 561200 | W9: 258200 | X9: 69150 | Y9: 73450 | Z9: 0 | AA9: #REF! | AB9: =W9+X9+Y9 -> 400800
A10: 45995 | B10: #REF! | C10: #REF! | D10: #REF! | E10: #REF! | F10: 0 | G10: #REF! | H10: #REF! | I10: #REF! | J10: #REF! | K10: 0 | L10: #REF! | N10: 46057 | O10: 88300 | P10: 105200 | Q10: 266050 | R10: 114500 | S10: 110350 | T10: 0 | U10: #REF! | V10: 574050 | W10: 245000 | X10: 60200 | Y10: 66200 | Z10: 0 | AA10: #REF! | AB10: =W10+X10+Y10 -> 371400
A11: 45996 | B11: #REF! | C11: #REF! | D11: #REF! | E11: #REF! | F11: 0 | G11: #REF! | H11: #REF! | I11: #REF! | J11: #REF! | K11: 0 | L11: #REF! | N11: 46058 | O11: 96950 | P11: 107650 | Q11: 250600 | R11: 98750 | S11: 97500 | T11: 0 | U11: #REF! | V11: 553950 | W11: 260050 | X11: 69050 | Y11: 66400 | Z11: 0 | AA11: #REF! | AB11: =W11+X11+Y11 -> 395500
A12: 45997 | B12: #REF! | C12: #REF! | D12: #REF! | E12: #REF! | F12: 0 | G12: #REF! | H12: #REF! | I12: #REF! | J12: #REF! | K12: 0 | L12: #REF! | N12: 46059 | O12: 98650 | P12: 103750 | Q12: 245750 | R12: 99300 | S12: 101150 | T12: 0 | U12: #REF! | V12: 547450 | W12: 254100 | X12: 68650 | Y12: 71500 | Z12: 0 | AA12: #REF! | AB12: =W12+X12+Y12 -> 394250
A13: 45998 | B13: #REF! | C13: #REF! | D13: #REF! | E13: #REF! | F13: 0 | G13: #REF! | H13: #REF! | I13: #REF! | J13: #REF! | K13: 0 | L13: #REF! | N13: 46060 | O13: 107900 | P13: 104000 | Q13: 250900 | R13: 106300 | S13: 105650 | T13: 0 | U13: #REF! | V13: 569100 | W13: 250550 | X13: 65450 | Y13: 62950 | Z13: 0 | AA13: #REF! | AB13: =W13+X13+Y13 -> 378950
A14: 45999 | B14: #REF! | C14: #REF! | D14: #REF! | E14: #REF! | F14: 0 | G14: #REF! | H14: #REF! | I14: #REF! | J14: #REF! | K14: 0 | L14: #REF! | N14: 46061 | O14: 108250 | P14: 107150 | Q14: 237900 | R14: 105550 | S14: 110700 | T14: 0 | U14: #REF! | V14: 558850 | W14: 271950 | X14: 75100 | Y14: 66300 | Z14: 0 | AA14: #REF! | AB14: =W14+X14+Y14 -> 413350
A15: 46000 | B15: #REF! | C15: #REF! | D15: #REF! | E15: #REF! | F15: 0 | G15: #REF! | H15: #REF! | I15: #REF! | J15: #REF! | K15: 0 | L15: #REF! | N15: 46062 | O15: 89400 | P15: 101100 | Q15: 263900 | R15: 95050 | S15: 105350 | T15: 0 | U15: #REF! | V15: 549450 | W15: 259100 | X15: 61800 | Y15: 64700 | Z15: 0 | AA15: #REF! | AB15: =W15+X15+Y15 -> 385600
A16: 46001 | B16: #REF! | C16: #REF! | D16: #REF! | E16: #REF! | F16: 0 | G16: #REF! | H16: #REF! | I16: #REF! | J16: #REF! | K16: 0 | L16: #REF! | N16: 46063 | O16: 114000 | P16: 105000 | Q16: 259050 | R16: 93400 | S16: 109100 | T16: 0 | U16: #REF! | V16: 571450 | W16: 232850 | X16: 66150 | Y16: 72550 | Z16: 0 | AA16: #REF! | AB16: =W16+X16+Y16 -> 371550
A17: 46002 | B17: #REF! | C17: #REF! | D17: #REF! | E17: #REF! | F17: 0 | G17: #REF! | H17: #REF! | I17: #REF! | J17: #REF! | K17: 0 | L17: #REF! | N17: 46064 | O17: 94850 | P17: 106800 | Q17: 256400 | R17: 95700 | S17: 101200 | T17: 0 | U17: #REF! | V17: 553750 | W17: 262050 | X17: 70100 | Y17: 68250 | Z17: 0 | AA17: #REF! | AB17: =W17+X17+Y17 -> 400400
A18: 46003 | B18: #REF! | C18: #REF! | D18: #REF! | E18: #REF! | F18: 0 | G18: #REF! | H18: #REF! | I18: #REF! | J18: #REF! | K18: 0 | L18: #REF! | N18: 46065 | O18: 99250 | P18: 101800 | Q18: 268400 | R18: 107550 | S18: 102600 | T18: 0 | U18: #REF! | V18: 577000 | W18: 267350 | X18: 77200 | Y18: 67550 | Z18: 0 | AA18: #REF! | AB18: =W18+X18+Y18 -> 412100
A19: 46004 | B19: #REF! | C19: #REF! | D19: #REF! | E19: #REF! | F19: 0 | G19: #REF! | H19: #REF! | I19: #REF! | J19: #REF! | K19: 0 | L19: #REF! | N19: 46066 | O19: 102950 | P19: 107950 | Q19: 259200 | R19: 102400 | S19: 97150 | T19: 0 | U19: #REF! | V19: 572500 | W19: 229650 | X19: 71550 | Y19: 75600 | Z19: 0 | AA19: #REF! | AB19: =W19+X19+Y19 -> 376800
... A36: 46021 | B36: #REF! | C36: #REF! | D36: #REF! | E36: #REF! | F36: 0 | G36: #REF! | H36: #REF! | I36: #REF! | J36: #REF! | K36: 0 | L36: #REF! | N36: 46083 | O36: 0 | P36: 0 | Q36: 0 | R36: 0 | S36: 0 | T36: 0 | U36: #REF! | V36: 0 | W36: 0 | X36: 0 | Y36: 0 | Z36: 0 | AA36: #REF! | AB36: =W36+X36+Y36 -> 0
N37: 46084 | O37: 0 | P37: 0 | Q37: 0 | R37: 0 | S37: 0 | T37: 0 | U37: #REF! | V37: 0 | W37: 0 | X37: 0 | Y37: 0 | Z37: 0

Sheet Sum No Cek Saldo
A1: {=_xlfn.UNIQUE(#REF!)} -> #REF!
B2: {=IFERROR(SUMIFS(#REF!,#REF!,$A2:$A$2000,#REF!,"<>*CEK SALDO*"),)} -> 0
B3: 0
B4: 0
B5: 0
B6: 0
B7: 0
B8: 0
B9: 0
B10: 0
B11: 0
B12: 0
B13: 0
B14: 0
... B2000: 0
